Workbook

Sheet REKAP KOM-LEM JUL 26
A3: KOMISI & LEMBUR
A4: NO | B4: NAMA TERAPIS | C4: TANGGAL | BM4: JUMLAH
C5: KOMISI | D5: LEMBUR | E5: KOMISI | F5: LEMBUR | G5: KOMISI | H5: LEMBUR | I5: KOMISI | J5: LEMBUR | K5: KOMISI | L5: LEMBUR | M5: KOMISI | N5: LEMBUR | O5: KOMISI | P5: LEMBUR | Q5: KOMISI | R5: LEMBUR | S5: KOMISI | T5: LEMBUR | U5: KOMISI | V5: LEMBUR | W5: KOMISI | X5: LEMBUR | Y5: KOMISI | Z5: LEMBUR | AA5: KOMISI | AB5: LEMBUR | AC5: KOMISI | AD5: LEMBUR | AE5: KOMISI | AF5: LEMBUR | AG5: KOMISI | AH5: LEMBUR | AI5: KOMISI | AJ5: LEMBUR | AK5: KOMISI | AL5: LEMBUR | AM5: KOMISI | AN5: LEMBUR | AO5: KOMISI | AP5: LEMBUR | AQ5: KOMISI | AR5: LEMBUR | AS5: KOMISI | AT5: LEMBUR | AU5: KOMISI | AV5: LEMBUR | AW5: KOMISI | AX5: LEMBUR | AY5: KOMISI | AZ5: LEMBUR | BA5: KOMISI | BB5: LEMBUR | BC5: KOMISI | BD5: LEMBUR | BE5: KOMISI | BF5: LEMBUR | BG5: KOMISI | BH5: LEMBUR | BI5: KOMISI | BJ5: LEMBUR | BK5: KOMISI | BL5: LEMBUR | BM5: KOMISI | BN5: LEMBUR | BO5: JUMLAH ALL
C6: 1 | E6: =+C6+1 -> 2 | G6: =+E6+1 -> 3 | I6: =+G6+1 -> 4 | K6: =+I6+1 -> 5 | M6: =+K6+1 -> 6 | O6: =+M6+1 -> 7 | Q6: =+O6+1 -> 8 | S6: =+Q6+1 -> 9 | U6: =+S6+1 -> 10 | W6: =+U6+1 -> 11 | Y6: =+W6+1 -> 12 | AA6: =+Y6+1 -> 13 | AC6: =+AA6+1 -> 14 | AE6: =+AC6+1 -> 15 | AG6: =+AE6+1 -> 16 | AI6: =+AG6+1 -> 17 | AK6: =+AI6+1 -> 18 | AM6: =+AK6+1 -> 19 | AO6: =+AM6+1 -> 20 | AQ6: =+AO6+1 -> 21 | AS6: =+AQ6+1 -> 22 | AU6: =+AS6+1 -> 23 | AW6: =+AU6+1 -> 24 | AY6: =+AW6+1 -> 25 | BA6: =+AY6+1 -> 26 | BC6: =+BA6+1 -> 27 | BE6: =+BC6+1 -> 28 | BG6: =+BE6+1 -> 29 | BI6: =+BG6+1 -> 30 | BK6: =+BI6+1 -> 31
A7: 1 | B7: VINA | C7: =+'[1]1 Juli 2026'!$M$5 -> 0 | E7: =+'[1]2 Juli 2026'!$M$5 -> 34000 | G7: =+'[1]3 Juli 2026'!$M$5 -> 0 | I7: =+'[1]4 Juli 2026'!$M$5 -> 27950 | J7: =+'[1]4 Juli 2026'!$N$5 -> 15000 | K7: =+'[1]5 Juli 2026'!$M$5 -> 26250 | M7: =+'[1]6 Juli 2026'!$M$5 -> 23500 | O7: =+'[1]7 Juli 2026'!$M$5 -> 0 | Q7: =+'[1]8 Juli 2026'!$M$5 -> 23876.25 | S7: =+'[1]9 Juli 2026'!$M$5 -> 20500 | T7: =+'[1]9 Juli 2026'!$N$5 -> 15000 | U7: =+'[1]10 Juli 2026'!$M$5 -> 6250 | W7: =+'[1]11 Juli 2026'!$M$5 -> 22000 | X7: =+'[1]11 Juli 2026'!$N$5 -> 15000 | Y7: =+'[1]12 Juli 2026'!$M$5 -> 39400 | Z7: =+'[1]12 Juli 2026'!$N$5 -> 15000 | AA7: =+'[1]13 Juli 2026'!$M$5 -> 0 | AC7: =+'[1]14 Juli 2026'!$M$5 -> 0 | AE7: =+'[1]15 Juli 2026'!$M$5 -> 32450 | AF7: =+'[1]15 Juli 2026'!$N$5 -> 15000 | AG7: =+'[1]16 Juli 2026'!$M$5 -> 0 | AI7: =+'[1]17 Juli 2026'!$M$5 -> 5500 | AK7: =+'[1]18 Juli 2026'!$M$5 -> 23000 | AL7: =+'[1]18 Juli 2026'!$N$5 -> 15000 | AM7: =+'[2]19 Juli 2026'!$M$5 -> 28750 | AO7: =+'[2]20 Juli 2026'!$M$5 -> 28750 | AQ7: =+'[2]21 Juli 2026'!$M$5 -> 33250 | AR7: =+'[2]21 Juli 2026'!$N$5 -> 15000 | AS7: =+'[2]22 Juli 2026'!$M$5 -> 38275 | AT7: =+'[2]22 Juli 2026'!$N$5 -> 15000 | AU7: =+'[2]23 Juli 2026'!$M$5 -> 27000 | AW7: =+'[3]24 Juli 2026'!$M$5 -> 16000 | AY7: =+'[3]25 Juli 2026'!$M$5 -> 0 | BA7: =+'[4]26 Juli 2026'!$M$5 -> 24750 | BB7: =+'[4]26 Juli 2026'!$N$5 -> 15000 | BC7: =+'[4]27 Juli 2026'!$M$5 -> 10525 | BE7: =+'[4]28 Juli 2026'!$M$5 -> 25775 | BF7: =+'[4]28 Juli 2026'!$N$5 -> 15000 | BG7: =+'[5]29 Juli 2026'!$M$5 -> 36435 | BI7: =+'[5]30 Juli 2026'!$M$5 -> 40250 | BJ7: =+'[5]30 Juli 2026'!$N$5 -> 15000 | BK7: =+'[6]31 Juli 2026'!$M$5 -> 22750 | BL7: =+'[6]31 Juli 2026'!$N$5 -> 15000 | BM7: =+C7+E7+G7+I7+K7+M7+O7+Q7+S7+U7+W7+Y7+AA7+AC7+AE7+AG7+AI7+AK7+AM7+AO7+AQ7+AS7+AU7+AW7+AY7+BA7+BC7+BE7+BG7+BI7+BK7 -> 617186.25 | BN7: =+D7+F7+H7+J7+L7+N7+P7+R7+T7+V7+X7+Z7+AB7+AD7+AF7+AH7+AJ7+AL7+AN7+AP7+AR7+AT7+AV7+AX7+AZ7+BB7+BD7+BF7+BH7+BJ7+BL7 -> 180000 | BO7: =+BM7+BN7 -> 797186.25
A8: =+A7+1 -> 2 | C8: =+'[1]1 Juli 2026'!$M$6 -> 30500 | D8: =+'[1]1 Juli 2026'!$N$6 -> 15000 | E8: =+'[1]2 Juli 2026'!$M$6 -> 0 | G8: =+'[1]3 Juli 2026'!$M$6 -> 28750 | I8: =+'[1]4 Juli 2026'!$M$6 -> 35500 | J8: =+'[1]4 Juli 2026'!$N$6 -> 15000 | K8: =+'[1]5 Juli 2026'!$M$6 -> 39900 | L8: =+'[1]5 Juli 2026'!$N$6 -> 15000 | M8: =+'[1]6 Juli 2026'!$M$6 -> 0 | O8: =+'[1]7 Juli 2026'!$M$6 -> 12250 | Q8: =+'[1]8 Juli 2026'!$M$6 -> 46150 | R8: =+'[1]8 Juli 2026'!$N$6 -> 15000 | S8: =+'[1]9 Juli 2026'!$M$6 -> 23937.5 | U8: =+'[1]10 Juli 2026'!$M$6 -> 13500 | W8: =+'[1]11 Juli 2026'!$M$6 -> 35900 | Y8: =+'[1]12 Juli 2026'!$M$6 -> 38400 | Z8: =+'[1]12 Juli 2026'!$N$6 -> 15000 | AA8: =+'[1]13 Juli 2026'!$M$6 -> 33060 | AC8: =+'[1]14 Juli 2026'!$M$6 -> 20225 | AD8: =+'[1]14 Juli 2026'!$N$6 -> 15000 | AE8: =+'[1]15 Juli 2026'!$M$6 -> 0 | AG8: =+'[1]16 Juli 2026'!$M$6 -> 12750 | AI8: =+'[1]17 Juli 2026'!$M$6 -> 16000 | AJ8: =+'[1]17 Juli 2026'!$N$6 -> 15000 | AK8: =+'[1]18 Juli 2026'!$M$6 -> 27000 | AM8: =+'[2]19 Juli 2026'!$M$6 -> 31000 | AO8: =+'[2]20 Juli 2026'!$M$6 -> 16225 | AQ8: =+'[2]21 Juli 2026'!$M$6 -> 26000 | AR8: =+'[2]21 Juli 2026'!$N$6 -> 15000 | AS8: =+'[2]22 Juli 2026'!$M$6 -> 36250 | AT8: =+'[2]22 Juli 2026'!$N$6 -> 15000 | AU8: =+'[2]23 Juli 2026'!$M$6 -> 0 | AW8: =+'[3]24 Juli 2026'!$M$6 -> 14750 | AX8: =+'[3]24 Juli 2026'!$N$6 -> 15000 | AY8: =+'[3]25 Juli 2026'!$M$6 -> 38550 | AZ8: =+'[3]25 Juli 2026'!$N$6 -> 15000 | BA8: =+'[4]26 Juli 2026'!$M$6 -> 25000 | BC8: =+'[4]27 Juli 2026'!$M$6 -> 23400 | BD8: =+'[4]27 Juli 2026'!$N$6 -> 15000 | BE8: =+'[4]28 Juli 2026'!$M$6 -> 31250 | BG8: =+'[5]29 Juli 2026'!$M$6 -> 25000 | BH8: =+'[5]29 Juli 2026'!$N$6 -> 15000 | BI8: =+'[5]30 Juli 2026'!$M$6 -> 0 | BK8: =+'[6]31 Juli 2026'!$M$6 -> 36725 | BL8: =+'[6]31 Juli 2026'!$N$6 -> 15000 | BM8: =+C8+E8+G8+I8+K8+M8+O8+Q8+S8+U8+W8+Y8+AA8+AC8+AE8+AG8+AI8+AK8+AM8+AO8+AQ8+AS8+AU8+AW8+AY8+BA8+BC8+BE8+BG8+BI8+BK8 -> 717972.5 | BN8: =+D8+F8+H8+J8+L8+N8+P8+R8+T8+V8+X8+Z8+AB8+AD8+AF8+AH8+AJ8+AL8+AN8+AP8+AR8+AT8+AV8+AX8+AZ8+BB8+BD8+BF8+BH8+BJ8+BL8 -> 210000 | BO8: =+BM8+BN8 -> 927972.5
A9: =+A8+1 -> 3 | C9: =+'[1]1 Juli 2026'!$M$7 -> 0 | E9: =+'[1]2 Juli 2026'!$M$7 -> 28500 | G9: =+'[1]3 Juli 2026'!$M$7 -> 0 | I9: =+'[1]4 Juli 2026'!$M$7 -> 26750 | J9: =+'[1]4 Juli 2026'!$N$7 -> 15000 | K9: =+'[1]5 Juli 2026'!$M$7 -> 48900 | L9: =+'[1]5 Juli 2026'!$N$7 -> 15000 | M9: =+'[1]6 Juli 2026'!$M$7 -> 16525 | O9: =+'[1]7 Juli 2026'!$M$7 -> 0 | Q9: =+'[1]8 Juli 2026'!$M$7 -> 37712.5 | R9: =+'[1]8 Juli 2026'!$N$7 -> 15000 | S9: =+'[1]9 Juli 2026'!$M$7 -> 18500 | T9: =+'[1]9 Juli 2026'!$N$7 -> 15000 | U9: =+'[1]10 Juli 2026'!$M$7 -> 25250 | W9: =+'[1]11 Juli 2026'!$M$7 -> 21800 | X9: =+'[1]11 Juli 2026'!$N$7 -> 15000 | Y9: =+'[1]12 Juli 2026'!$M$7 -> 34387.5 | Z9: =+'[1]12 Juli 2026'!$N$7 -> 15000 | AA9: =+'[1]13 Juli 2026'!$M$7 -> 1000 | AC9: =+'[1]14 Juli 2026'!$M$7 -> 27750 | AD9: =+'[1]14 Juli 2026'!$N$7 -> 15000 | AE9: =+'[1]15 Juli 2026'!$M$7 -> 24185 | AG9: =+'[1]16 Juli 2026'!$M$7 -> 0 | AI9: =+'[1]17 Juli 2026'!$M$7 -> 9750 | AK9: =+'[1]18 Juli 2026'!$M$7 -> 26750 | AM9: =+'[2]19 Juli 2026'!$M$7 -> 34650 | AN9: =+'[2]19 Juli 2026'!$N$7 -> 15000 | AO9: =+'[2]20 Juli 2026'!$M$7 -> 23500 | AQ9: =+'[2]21 Juli 2026'!$M$7 -> 21750 | AS9: =+'[2]22 Juli 2026'!$M$7 -> 26000 | AT9: =+'[2]22 Juli 2026'!$N$7 -> 15000 | AU9: =+'[2]23 Juli 2026'!$M$7 -> 31150 | AV9: =+'[2]23 Juli 2026'!$N$7 -> 15000 | AW9: =+'[3]24 Juli 2026'!$M$7 -> 0 | AY9: =+'[3]25 Juli 2026'!$M$7 -> 0 | BA9: =+'[4]26 Juli 2026'!$M$7 -> 29400 | BC9: =+'[6]27 Juli 2026'!$M$7 -> 9000 | BD9: =+'[4]27 Juli 2026'!$N$7 -> 15000 | BE9: =+'[4]28 Juli 2026'!$M$7 -> 19250 | BG9: =+'[5]29 Juli 2026'!$M$7 -> 21500 | BH9: =+'[5]29 Juli 2026'!$N$7 -> 15000 | BI9: =+'[5]30 Juli 2026'!$M$7 -> 36750 | BK9: =+'[6]31 Juli 2026'!$M$8 -> 44075 | BL9: =+'[6]31 Juli 2026'!$N$8 -> 15000 | BM9: =+C9+E9+G9+I9+K9+M9+O9+Q9+S9+U9+W9+Y9+AA9+AC9+AE9+AG9+AI9+AK9+AM9+AO9+AQ9+AS9+AU9+AW9+AY9+BA9+BC9+BE9+BG9+BI9+BK9 -> 644785 | BN9: =+D9+F9+H9+J9+L9+N9+P9+R9+T9+V9+X9+Z9+AB9+AD9+AF9+AH9+AJ9+AL9+AN9+AP9+AR9+AT9+AV9+AX9+AZ9+BB9+BD9+BF9+BH9+BJ9+BL9 -> 195000 | BO9: =+BM9+BN9 -> 839785
A10: =+A9+1 -> 4 | C10: =+'[1]1 Juli 2026'!$M$8 -> 0 | E10: =+'[1]2 Juli 2026'!$M$8 -> 26412.5 | F10: =+'[1]2 Juli 2026'!$N$8 -> 15000 | G10: =+'[1]3 Juli 2026'!$M$8 -> 38000 | H10: =+'[1]3 Juli 2026'!$N$8 -> 15000 | I10: =+'[1]4 Juli 2026'!$M$8 -> 24250 | J10: =+'[1]4 Juli 2026'!$N$8 -> 15000 | K10: =+'[1]5 Juli 2026'!$M$8 -> 28000 | L10: =+'[1]5 Juli 2026'!$N$8 -> 15000 | M10: =+'[1]6 Juli 2026'!$M$8 -> 0 | O10: =+'[1]7 Juli 2026'!$M$8 -> 28150 | P10: =+'[1]7 Juli 2026'!$N$8 -> 15000 | Q10: =+'[1]8 Juli 2026'!$M$8 -> 38750 | R10: =+'[1]8 Juli 2026'!$N$8 -> 15000 | S10: =+'[1]9 Juli 2026'!$M$8 -> 14000 | U10: =+'[1]10 Juli 2026'!$M$8 -> 15500 | W10: =+'[1]11 Juli 2026'!$M$8 -> 25750 | X10: =+'[1]11 Juli 2026'!$N$8 -> 15000 | Y10: =+'[1]12 Juli 2026'!$M$8 -> 38737.5 | Z10: =+'[1]12 Juli 2026'!$N$8 -> 15000 | AA10: =+'[1]13 Juli 2026'!$M$8 -> 26000 | AC10: =+'[1]14 Juli 2026'!$M$8 -> 0 | AE10: =+'[1]15 Juli 2026'!$M$8 -> 23237.5 | AF10: =+'[1]15 Juli 2026'!$N$8 -> 15000 | AG10: =+'[1]16 Juli 2026'!$M$8 -> 5000 | AI10: =+'[1]17 Juli 2026'!$M$8 -> 3000 | AK10: =+'[1]18 Juli 2026'!$M$8 -> 41900 | AL10: =+'[1]18 Juli 2026'!$N$8 -> 15000 | AM10: =+'[2]19 Juli 2026'!$M$8 -> 29475 | AN10: =+'[2]19 Juli 2026'!$N$8 -> 15000 | AO10: =+'[2]20 Juli 2026'!$M$8 -> 23750 | AP10: =+'[2]20 Juli 2026'!$N$8 -> 15000 | AS10: =+'[2]22 Juli 2026'!$M$8 -> 27462.5 | AU10: =+'[2]23 Juli 2026'!$M$8 -> 12162.5 | AV10: =+'[2]23 Juli 2026'!$N$8 -> 15000 | AW10: =+'[3]24 Juli 2026'!$M$8 -> 30962.5 | AX10: =+'[3]24 Juli 2026'!$N$8 -> 15000 | AY10: =+'[3]25 Juli 2026'!$M$8 -> 29775 | AZ10: =+'[3]25 Juli 2026'!$N$8 -> 0 | BA10: =+'[4]26 Juli 2026'!$M$8 -> 21250 | BB10: =+'[4]26 Juli 2026'!$N$8 -> 15000 | BC10: =+'[4]27 Juli 2026'!$M$8 -> 15500 | BD10: =+'[4]27 Juli 2026'!$N$8 -> 15000 | BE10: =+'[4]28 Juli 2026'!$M$8 -> 0 | BG10: =+'[5]29 Juli 2026'!$M$8 -> 23750 | BH10: =+'[5]29 Juli 2026'!$N$8 -> 15000 | BI10: =+'[5]30 Juli 2026'!$M$8 -> 16875 | BK10: =+'[6]31 Juli 2026'!$M$9 -> 25250 | BL10: =+'[6]31 Juli 2026'!$N$9 -> 15000 | BM10: =+C10+E10+G10+I10+K10+M10+O10+Q10+S10+U10+W10+Y10+AA10+AC10+AE10+AG10+AI10+AK10+AM10+AO10+AQ10+AS10+AU10+AW10+AY10+BA10+BC10+BE10+BG10+BI10+BK10 -> 632900 | BN10: =+D10+F10+H10+J10+L10+N10+P10+R10+T10+V10+X10+Z10+AB10+AD10+AF10+AH10+AJ10+AL10+AN10+AP10+AR10+AT10+AV10+AX10+AZ10+BB10+BD10+BF10+BH10+BJ10+BL10 -> 270000 | BO10: =+BM10+BN10 -> 902900
A11: =+A10+1 -> 5 | C11: =+'[1]1 Juli 2026'!$M$10 -> 22250 | D11: =+'[1]1 Juli 2026'!$N$10 -> 15000 | E11: =+'[1]2 Juli 2026'!$M$10 -> 0 | G11: =+'[1]3 Juli 2026'!$M$10 -> 40750 | H11: =+'[1]3 Juli 2026'!$N$10 -> 15000 | I11: =+'[1]4 Juli 2026'!$M$10 -> 37400 | J11: =+'[1]4 Juli 2026'!$N$10 -> 15000 | K11: =+'[1]5 Juli 2026'!$M$10 -> 40250 | L11: =+'[1]5 Juli 2026'!$N$10 -> 15000 | M11: =+'[1]6 Juli 2026'!$M$10 -> 19887.5 | N11: =+'[1]6 Juli 2026'!$N$10 -> 15000 | O11: =+'[1]7 Juli 2026'!$M$10 -> 13750 | Q11: =+'[1]8 Juli 2026'!$M$10 -> 23437.5 | S11: =+'[1]9 Juli 2026'!$M$10 -> 21000 | T11: =+'[1]9 Juli 2026'!$N$10 -> 15000 | U11: =+'[1]10 Juli 2026'!$M$10 -> 19000 | W11: =+'[1]11 Juli 2026'!$M$10 -> 29750 | X11: =+'[1]11 Juli 2026'!$N$10 -> 15000 | Y11: =+'[1]12 Juli 2026'!$M$10 -> 31875 | Z11: =+'[1]12 Juli 2026'!$N$10 -> 15000 | AA11: =+'[1]13 Juli 2026'!$M$10 -> 32625 | AC11: =+'[1]14 Juli 2026'!$M$10 -> 0 | AE11: =+'[1]15 Juli 2026'!$M$10 -> 31875 | AF11: =+'[1]15 Juli 2026'!$N$10 -> 15000 | AG11: =+'[1]16 Juli 2026'!$M$10 -> 0 | AI11: =+'[1]17 Juli 2026'!$M$10 -> 6500 | AK11: =+'[1]18 Juli 2026'!$M$10 -> 25000 | AM11: =+'[2]19 Juli 2026'!$M$10 -> 36500 | AN11: =+'[2]19 Juli 2026'!$N$10 -> 15000 | AO11: =+'[2]20 Juli 2026'!$M$10 -> 23750 | AQ11: =+'[2]21 Juli 2026'!$M$10 -> 24500 | AR11: =+'[2]21 Juli 2026'!$N$10 -> 15000 | AS11: =+'[2]22 Juli 2026'!$M$10 -> 0 | AU11: =+'[2]23 Juli 2026'!$M$10 -> 11250 | AV11: =+'[2]23 Juli 2026'!$N$10 -> 15000 | AW11: =+'[3]24 Juli 2026'!$M$10 -> 25500 | AY11: =+'[3]25 Juli 2026'!$M$10 -> 25750 | AZ11: =+'[3]25 Juli 2026'!$N$10 -> 15000 | BA11: =+'[4]26 Juli 2026'!$M$10 -> 27000 | BC11: =+'[4]27 Juli 2026'!$M$10 -> 0 | BE11: =+'[4]28 Juli 2026'!$M$10 -> 22450 | BF11: =+'[4]28 Juli 2026'!$N$10 -> 15000 | BG11: =+'[5]29 Juli 2026'!$M$10 -> 21000 | BI11: =+'[5]30 Juli 2026'!$M$10 -> 23250 | BJ11: =+'[5]30 Juli 2026'!$N$10 -> 15000 | BK11: =+'[6]31 Juli 2026'!$M$11 -> 0 | BM11: =+C11+E11+G11+I11+K11+M11+O11+Q11+S11+U11+W11+Y11+AA11+AC11+AE11+AG11+AI11+AK11+AM11+AO11+AQ11+AS11+AU11+AW11+AY11+BA11+BC11+BE11+BG11+BI11+BK11 -> 636300 | BN11: =+D11+F11+H11+J11+L11+N11+P11+R11+T11+V11+X11+Z11+AB11+AD11+AF11+AH11+AJ11+AL11+AN11+AP11+AR11+AT11+AV11+AX11+AZ11+BB11+BD11+BF11+BH11+BJ11+BL11 -> 225000 | BO11: =+BM11+BN11 -> 861300
A12: =+A11+1 -> 6 | C12: =+'[1]1 Juli 2026'!$M$11 -> 31112.5 | D12: =+'[1]1 Juli 2026'!$N$11 -> 15000 | E12: =+'[1]2 Juli 2026'!$M$11 -> 36087.5 | F12: =+'[1]2 Juli 2026'!$N$11 -> 15000 | G12: =+'[1]3 Juli 2026'!$M$11 -> 43150 | I12: =+'[1]4 Juli 2026'!$M$11 -> 44250 | J12: =+'[1]4 Juli 2026'!$N$11 -> 15000 | K12: =+'[1]5 Juli 2026'!$M$11 -> 38000 | L12: =+'[1]5 Juli 2026'!$N$11 -> 15000 | M12: =+'[1]6 Juli 2026'!$M$11 -> 14250 | O12: =+'[1]7 Juli 2026'!$M$11 -> 35375 | P12: =+'[1]7 Juli 2026'!$N$11 -> 15000 | Q12: =+'[1]8 Juli 2026'!$M$11 -> 34500 | R12: =+'[1]8 Juli 2026'!$N$11 -> 15000 | S12: =+'[1]9 Juli 2026'!$M$11 -> 0 | U12: =+'[1]10 Juli 2026'!$M$11 -> 26500 | V12: =+'[1]10 Juli 2026'!$N$11 -> 15000 | W12: =+'[1]11 Juli 2026'!$M$11 -> 25950 | X12: =+'[1]11 Juli 2026'!$N$11 -> 15000 | Y12: =+'[1]12 Juli 2026'!$M$11 -> 30887.5 | Z12: =+'[1]12 Juli 2026'!$N$11 -> 15000 | AA12: =+'[1]13 Juli 2026'!$M$11 -> 0 | AC12: =+'[1]14 Juli 2026'!$M$11 -> 22500 | AE12: =+'[1]15 Juli 2026'!$M$11 -> 23750 | AG12: =+'[1]16 Juli 2026'!$M$11 -> 9750 | AI12: =+'[1]17 Juli 2026'!$M$11 -> 15000 | AJ12: =+'[1]17 Juli 2026'!$N$11 -> 15000 | AK12: =+'[1]18 Juli 2026'!$M$11 -> 40400 | AL12: =+'[1]18 Juli 2026'!$N$11 -> 15000 | AM12: =+'[2]19 Juli 2026'!$M$11 -> 20375 | AN12: =+'[2]19 Juli 2026'!$N$11 -> 15000 | AO12: =+'[2]20 Juli 2026'!$M$11 -> 21887.5 | AP12: =+'[2]20 Juli 2026'!$N$11 -> 15000 | AS12: =+'[2]22 Juli 2026'!$M$11 -> 20425 | AT12: =+'[2]22 Juli 2026'!$N$11 -> 15000 | AU12: =+'[2]23 Juli 2026'!$M$11 -> 19100 | AV12: =+'[2]23 Juli 2026'!$N$11 -> 15000 | AW12: =+'[3]24 Juli 2026'!$M$11 -> 16500 | AY12: =+'[3]25 Juli 2026'!$M$11 -> 24250 | AZ12: =+'[3]25 Juli 2026'!$N$11 -> 15000 | BA12: =+'[4]26 Juli 2026'!$M$11 -> 16250 | BC12: =+'[4]27 Juli 2026'!$M$11 -> 14000 | BD12: =+'[4]27 Juli 2026'!$N$11 -> 15000 | BE12: =+'[4]28 Juli 2026'!$M$11 -> 26775 | BF12: =+'[4]28 Juli 2026'!$N$11 -> 15000 | BG12: =+'[5]29 Juli 2026'!$M$11 -> 0 | BI12: =+'[5]30 Juli 2026'!$M$11 -> 29750 | BJ12: =+'[5]30 Juli 2026'!$N$11 -> 15000 | BK12: =+'[6]31 Juli 2026'!$M$12 -> 47442.5 | BL12: =+'[6]31 Juli 2026'!$N$12 -> 15000 | BM12: =+C12+E12+G12+I12+K12+M12+O12+Q12+S12+U12+W12+Y12+AA12+AC12+AE12+AG12+AI12+AK12+AM12+AO12+AQ12+AS12+AU12+AW12+AY12+BA12+BC12+BE12+BG12+BI12+BK12 -> 728217.5 | BN12: =+D12+F12+H12+J12+L12+N12+P12+R12+T12+V12+X12+Z12+AB12+AD12+AF12+AH12+AJ12+AL12+AN12+AP12+AR12+AT12+AV12+AX12+AZ12+BB12+BD12+BF12+BH12+BJ12+BL12 -> 300000 | BO12: =+BM12+BN12 -> 1028217.5
A13: =+A12+1 -> 7 | AY13: =+'[3]25 Juli 2026'!$M$9 -> 14575 | AZ13: =+'[3]25 Juli 2026'!$N$9 -> 15000 | BG13: =+'[5]29 Juli 2026'!$M$9 -> 4750 | BI13: =+'[5]30 Juli 2026'!$M$9 -> 7250 | BJ13: =+'[5]30 Juli 2026'!$N$11 -> 15000 | BK13: =+'[6]31 Juli 2026'!$M$10 -> 18750 | BL13: =+'[6]31 Juli 2026'!$N$10 -> 15000 | BM13: =+C13+E13+G13+I13+K13+M13+O13+Q13+S13+U13+W13+Y13+AA13+AC13+AE13+AG13+AI13+AK13+AM13+AO13+AQ13+AS13+AU13+AW13+AY13+BA13+BC13+BE13+BG13+BI13+BK13 -> 45325 | BN13: =+D13+F13+H13+J13+L13+N13+P13+R13+T13+V13+X13+Z13+AB13+AD13+AF13+AH13+AJ13+AL13+AN13+AP13+AR13+AT13+AV13+AX13+AZ13+BB13+BD13+BF13+BH13+BJ13+BL13 -> 45000 | BO13: =+BM13+BN13 -> 90325
A14: JUMLAH | C14: =SUM(C7:C13) -> 83862.5 | D14: =SUM(D7:D13) -> 45000 | E14: =SUM(E7:E13) -> 125000 | F14: =SUM(F7:F13) -> 30000 | G14: =SUM(G7:G13) -> 150650 | H14: =SUM(H7:H13) -> 30000 | I14: =SUM(I7:I13) -> 196100 | J14: =SUM(J7:J13) -> 90000 | ... BO14: =SUM(BO7:BO13) -> 5447686.2
B19: =1 -> 1 | C19: =+'[7]1 Juli 2026'!$H$23 -> 1642250 | D19: =+'[7]1 Juli 2026'!$O$13 -> 130612.5 | E19: =+'[7]1 Juli 2026'!$P$20 -> 20000
B20: =1+B19 -> 2 | C20: =+'[7]2 Juli 2026'!$H$23 -> 2430000 | D20: =+'[7]2 Juli 2026'!$O$13 -> 155000 | E20: =+'[7]2 Juli 2026'!$P$20 -> 20000
B21: =1+B20 -> 3 | C21: =+'[7]3 Juli 2026'!$H$25 -> 3310000 | D21: =+'[7]1 Juli 2026'!$O$13 -> 130612.5 | E21: =+'[7]1 Juli 2026'!$P$20 -> 20000
B22: =1+B21 -> 4 | C22: =+'[7]4 Juli 2026'!$H$27 -> 3820000 | D22: =+'[7]4 Juli 2026'!$O$13 -> 286100 | E22: =+'[7]4 Juli 2026'!$P$21 -> 88000
B23: =1+B22 -> 5 | C23: =+'[7]5 Juli 2026'!$H$29 -> 4085000 | D23: =+'[7]5 Juli 2026'!$O$13 -> 323550 | E23: =+'[7]5 Juli 2026'!$P$21 -> 64000
B24: =1+B23 -> 6 | C24: =+'[7]6 Juli 2026'!$H$17 -> 1658650 | D24: =+'[7]6 Juli 2026'!$O$13 -> 94912.5 | E24: =+'[7]6 Juli 2026'!$P$19 -> 20000
B25: =1+B24 -> 7 | C25: =+'[7]7 Juli 2026'!$H$17 -> 1692500 | D25: =+'[7]7 Juli 2026'!$O$13 -> 119525 | E25: =+'[7]7 Juli 2026'!$P$19 -> 37000
B26: =1+B25 -> 8 | C26: =+'[7]8 Juli 2026'!$H$25 -> 3850525 | D26: =+'[7]8 Juli 2026'!$O$13 -> 264426.25 | E26: =+'[7]8 Juli 2026'!$P$21 -> 81000
B27: =1+B26 -> 9 | C27: =+'[7]9 Juli 2026'!$H$18 -> 1958750 | D27: =+'[7]9 Juli 2026'!$O$13 -> 142937.5 | E27: =+'[7]9 Juli 2026'!$P$19 -> 20000
B28: =1+B27 -> 10 | C28: =+'[7]10 Juli 2026'!$H$23 -> 2050000 | D28: =+'[7]10 Juli 2026'!$O$13 -> 121000 | E28: =+'[7]10 Juli 2026'!$P$19 -> 36000
B29: =1+B28 -> 11 | C29: =+'[7]11 Juli 2026'!$H$27 -> 3157375 | D29: =+'[7]11 Juli 2026'!$O$12 -> 236150 | E29: =+'[7]11 Juli 2026'!$P$18 -> 20000
B30: =1+B29 -> 12 | C30: =+'[7]12 Juli 2026'!$H$31 -> 4011250 | D30: =+'[7]12 Juli 2026'!$O$13 -> 303687.5 | E30: =+'[7]1 Juli 2026'!$P$20 -> 20000
B31: =1+B30 -> 13 | C31: =+'[7]13 Juli 2026'!$H$18 -> 1695500 | D31: =+'[7]13 Juli 2026'!$O$13 -> 92685 | E31: =+'[7]13 Juli 2026'!$P$20 -> 35000
B32: =1+B31 -> 14 | C32: =+'[7]14 Juli 2026'!$H$18 -> 1409500 | D32: =+'[7]14 Juli 2026'!$O$13 -> 100475 | E32: =+'[7]1 Juli 2026'!$P$20 -> 20000
B33: =1+B32 -> 15 | C33: =+'[7]15 Juli 2026'!$H$24 -> 2621750 | D33: =+'[7]15 Juli 2026'!$O$13 -> 180497.5 | E33: =+'[7]1 Juli 2026'!$P$20 -> 20000
B34: =1+B33 -> 16 | C34: =+'[7]16 Juli 2026'!$H$9 -> 550000 | D34: =+'[7]16 Juli 2026'!$O$13 -> 27500 | E34: =+'[7]1 Juli 2026'!$P$20 -> 20000
B35: =1+B34 -> 17 | C35: =+'[7]17 Juli 2026'!$H$15 -> 1260000 | D35: =+'[7]17 Juli 2026'!$O$13 -> 85750 | E35: =+'[7]17 Juli 2026'!$P$19 -> 20000
B36: =1+B35 -> 18 | C36: =+'[7]18 Juli 2026'!$H$29 -> 3825000 | D36: =+'[7]18 Juli 2026'!$O$13 -> 229050 | E36: =+'[7]18 Juli 2026'!$P$19 -> 39000
B37: =1+B36 -> 19 | C37: =+'[7]19 Juli 2026'!$H$25 -> 3517000 | D37: =+'[7]19 Juli 2026'!$O$13 -> 240750 | E37: =+'[7]19 Juli 2026'!$P$19 -> 20000
B38: =1+B37 -> 20 | C38: =+'[7]20 Juli 2026'!$H$25 -> 2762950 | D38: =+'[7]1 Juli 2026'!$O$13 -> 130612.5 | E38: =+'[7]20 Juli 2026'!$P$19 -> 20000
B39: =1+B38 -> 21 | C39: =+'[7]21 Juli 2026'!$H$18 -> 2255000 | D39: =+'[7]21 Juli 2026'!$O$13 -> 150500 | E39: =+'[7]1 Juli 2026'!$P$20 -> 20000
B40: =1+B39 -> 22 | C40: =+'[7]22 Juli 2026'!$H$26 -> 2968250 | D40: =+'[7]22 Juli 2026'!$O$13 -> 208412.5 | E40: =+'[7]22 Juli 2026'!$P$19 -> 40000
B41: =1+B40 -> 23 | C41: =+'[7]23 Juli 2026'!$H$21 -> 2365250 | D41: =+'[7]23 Juli 2026'!$O$13 -> 160662.5 | E41: =+'[7]23 Juli 2026'!$P$19 -> 66000
B42: =1+B41 -> 24 | C42: =+'[7]24 Juli 2026'!$H$17 -> 1934250 | D42: =+'[7]24 Juli 2026'!$O$13 -> 133712.5 | E42: =+'[7]24 Juli 2026'!$P$19 -> 20000
B43: =1+B42 -> 25 | C43: =+'[7]25 Juli 2026'!$H$24 -> 2560000 | D43: =+'[7]25 Juli 2026'!$O$12 -> 192900 | E43: =+'[7]25 Juli 2026'!$P$21 -> 73000
B44: =1+B43 -> 26 | C44: =+'[7]26 Juli 2026'!$H$16 -> 2705000 | D44: =+'[7]26 Juli 2026'!$O$13 -> 173650 | E44: =+'[7]26 Juli 2026'!$P$19 -> 20000
B45: =1+B44 -> 27 | C45: =+'[4]27 Juli 2026'!$H$16 -> 1625500 | D45: =+'[4]28 Juli 2026'!$O$13 -> 170500 | E45: =+'[4]28 Juli 2026'!$P$19 -> 20000
B46: =1+B45 -> 28 | C46: =+'[4]28 Juli 2026'!$H$20 -> 2510000 | D46: =+'[4]28 Juli 2026'!$O$13 -> 170500 | E46: =+'[4]28 Juli 2026'!$P$19 -> 20000
...

Sheet REKAP PENDAPATAN JUL 26
A1: NO | B1: NAMA | C1: POSISI | D1: JHK | E1: GP | F1: PENDAPATAN | G1: LEMBUR/U.MAKAN | I1: KOMISI | J1: BONUS | L1: TUNJANGAN | N1: PENDAPATAN | O1: MANGKIR | Q1: KETERLAMBATAN | S1: KASBON | T1: POT. | U1: JML | V1: PENDAPATAN
G2: HARI | H2: JML LMBR/U.MKN | J2: TARGET | K2: SERVICE EXCELENT, NO COMPLAIN, KEHADIRAN | L2: Kehadiran | M2: Lain2 | N2: KOTOR | O2: HARI | P2: JML MANGKIR | Q2: MENIT | R2: JML MENIT | T2: LAIN2 | U2: POTONGAN | V2: BERSIH
E3: RP | F3: RP | H3: RP | I3: RP | J3: RP | K3: RP | M3: RP | N3: RP | P3: RP | R3: RP | S3: RP | T3: RP | U3: RP | V3: RP
D4: (1) | E4: (2) | F4: (3) | H4: (4) | I4: (5) | J4: (6) | K4: (7) | M4: (8) | N4: (9) | P4: (10) | R4: (11) | S4: (12) | T4: (13) | U4: (14) | V4: (15)
A5: 1 | B5: VINA | C5: TERAPIS | D5: 26 | E5: 69230.769 | F5: =+D5*E5 -> 1800000 | H5: =+'REKAP KOM-LEM JUL 26'!BN7 -> 180000 | I5: =+'REKAP KOM-LEM JUL 26'!BM7 -> 617186.25 | J5: 0 | K5: 0 | M5: 0 | N5: =SUM(F5:M5) -> 2597186.2 | O5: 3 | P5: =+O5*E5 -> 207692.31 | Q5: 86 | R5: =+Q5*1000 -> 86000 | S5: 0 | T5: 0 | U5: =+P5+R5+S5+T5 -> 293692.31 | V5: =+N5-U5 -> 2303493.9
F6: =+D6*E6 -> 0 | N6: =+F6+H6+I6+J6+K6+M6 -> 0 | U6: =+P6+R6+S6+T6 -> 0 | V6: =+N6-U6 -> 0
F7: =+D7*E7 -> 0 | N7: =+F7+H7+I7+J7+K7+M7 -> 0 | U7: =+P7+R7+S7+T7 -> 0 | V7: =+N7-U7 -> 0
F8: =+D8*E8 -> 0 | N8: =+F8+H8+I8+J8+K8+M8 -> 0 | U8: =+P8+R8+S8+T8 -> 0 | V8: =+N8-U8 -> 0
F9: =+D9*E9 -> 0 | N9: =+F9+H9+I9+J9+K9+M9 -> 0 | U9: =+P9+R9+S9+T9 -> 0 | V9: =+N9-U9 -> 0
F10: =+D10*E10 -> 0 | N10: =+F10+H10+I10+J10+K10+M10 -> 0 | U10: =+P10+R10+S10+T10 -> 0 | V10: =+N10-U10 -> 0
F11: =+D11*E11 -> 0 | N11: =+F11+H11+I11+J11+K11+M11 -> 0 | U11: =+P11+R11+S11+T11 -> 0 | V11: =+N11-U11 -> 0
F12: 0 | N12: =+F12+H12+I12+J12+K12+L12+M12 -> 0 | U12: =+P12+R12+S12+T12 -> 0 | V12: =+N12-U12 -> 0
F13: =+D13*E13 -> 0 | N13: =+F13+H13+I13+J13+K13+M13 -> 0 | U13: =+P13+R13+S13+T13 -> 0 | V13: =+N13-U13 -> 0
F14: =+D14*E14 -> 0 | I14: 0 | K14: 0 | M14: 0 | N14: =+F14+H14+I14+J14+K14+M14 -> 0 | O14: 0 | P14: =+E14*O14 -> 0 | R14: =+Q14*1000 -> 0 | U14: =+P14+R14+S14+T14 -> 0 | V14: =+N14-U14 -> 0
H15: =+G15*12000 -> 0 | I15: 0 | J15: 0 | K15: 0 | N15: =+F15+H15+I15+J15+K15+M15 -> 0 | P15: =+E15*O15 -> 0 | R15: =+Q15*1000 -> 0 | U15: =+P15+R15+S15+T15 -> 0 | V15: =+N15-U15 -> 0
A16: JUMLAH | F16: =SUM(F5:F15) -> 1800000 | G16: =SUM(G5:G15) -> 0 | H16: =SUM(H5:H15) -> 180000 | I16: =SUM(I5:I15) -> 617186.25 | J16: =SUM(J5:J15) -> 0 | K16: =SUM(K5:K15) -> 0 | L16: =SUM(L5:L15) -> 0 | M16: =SUM(M5:M15) -> 0 | ... V16: =SUM(V5:V15) -> 2303493.9

Sheet SLIP GJ JUL 26
C3: SELESA SALON & SPA SEMARANG
C4: TANDA TERIMA PENDAPATAN
C6: Nama Karyawan | D6: : | E6: AGUSTINA (VINA)
C7: Jabatan | D7: : | E7: Terapis | G7: JHK | H7: : | I7: =+'REKAP PENDAPATAN JUL 26'!D5 -> 26 | J7: Hari
C8: Periode Gaji | D8: : | E8: Juli 2026 | G8: Tdk Masuk | H8: : | I8: =+'REKAP PENDAPATAN JUL 26'!O5 -> 3 | J8: Hari
C9: Status Pegawai | D9: : | E9: Tetap | G9: Keterlambatan | H9: : | I9: =+'REKAP PENDAPATAN JUL 26'!Q5 -> 86 | J9: Menit
C11: Komponen Gaji | E11: Hari/Menit | F11: Harsat | G11: Diterima (Rp) | H11: Keterangan
C12: Gaji Pokok | E12: =+I7 -> 26 | F12: =+'REKAP PENDAPATAN JUL 26'!E5 -> 69230.769 | G12: =+'REKAP PENDAPATAN JUL 26'!F5 -> 1800000
C13: Komisi | G13: =+'REKAP PENDAPATAN JUL 26'!I5 -> 617186.25
C14: Lembur | E14: 12 | F14: 15000 | G14: =+'REKAP PENDAPATAN JUL 26'!H5 -> 180000
C15: Tunjangan | G15: =+'REKAP PENDAPATAN JUL 26'!M5 -> 0
C16: Bonus | G16: =+'REKAP PENDAPATAN JUL 26'!K5 -> 0
C17: Titipan TIP | G17: 18000
C18: Pendapatan Kotor | G18: =+G12+G13+G14+G15+G16+G17 -> 2615186.2
C19: Potongan (Absensi, dll) | E19: =+I8 -> 3 | F19: =+F12 -> 69230.769 | G19: =+E19*F19 -> 207692.31 | H19: Pot. Tdk masuk
E20: =+I9 -> 86 | F20: 1000 | G20: =+E20*F20 -> 86000 | H20: Pot. Keterlambatan
C21: Jumlah Potongan | G21: =SUM(G19:G20) -> 293692.31
C22: Total Gaji Diterima | G22: =+G18-G21 -> 2321493.9
C24: Semarang, 04 Agustus 2026
C25: Tanda Tangan Penerima | D25: : | I25: Manajer / Pemilik
C28: =+E6 -> AGUSTINA (VINA) | I28: PRABA INTAN
C33: SELESA SALON & SPA SEMARANG
C34: TANDA TERIMA PENDAPATAN
C36: Nama Karyawan | D36: : | E36: PIKY APRILI (PIKY)
C37: Jabatan | D37: : | E37: Kasir | G37: JHK | H37: : | I37: =+'REKAP PENDAPATAN JUL 26'!D12 -> 0 | J37: Hari
C38: Periode Gaji | D38: : | E38: Juli 2026 | G38: Tdk Masuk | H38: : | I38: =+'REKAP PENDAPATAN JUL 26'!O223 -> 0 | J38: Hari
C39: Status Pegawai | D39: : | E39: Tetap | G39: Keterlambatan | H39: : | I39: =+'REKAP PENDAPATAN JUL 26'!Q76 -> 0 | J39: Menit
C41: Komponen Gaji | E41: Hari/Menit | F41: Harsat | G41: Diterima (Rp) | H41: Keterangan
C42: Gaji Pokok | E42: =+I37 -> 0 | F42: =+'REKAP PENDAPATAN JUL 26'!E12 -> 0 | G42: =+E42*F42-2 -> -2
C43: Lembur | E43: 22 | F43: 15000 | G43: =+E43*F43 -> 330000
C44: Tunjangan | G44: =+'REKAP PENDAPATAN JUL 26'!L12+'REKAP PENDAPATAN JUL 26'!M12 -> 0 | H44: Tunj Kos & Kehadiran
C45: Bonus | G45: =+'REKAP PENDAPATAN JUL 26'!K195 -> 0
C46: Titipan TIP | G46: 0
C47: Pendapatan Kotor | G47: =SUM(G42:G46) -> 329998
C48: Potongan (Absensi, dll) | E48: =+I38 -> 0 | F48: 0 | G48: =+E48*F48 -> 0
G49: 0
E50: =+I39 -> 0 | F50: 0 | G50: =+E50*F50 -> 0
C51: Jumlah Potongan | G51: =SUM(G48:G50) -> 0
C52: Total Gaji Diterima | G52: =+G47-G51 -> 329998
C54: Semarang, 04 Agustus 2026
...

Sheet REKAP STOK IN-OUT
A1: NO | B1: PRODUK | C1: TGL STOK MASUK | D1: JML PROD. MASUK | F1: BERAT GROSS PROD. MASUK | H1: DOSIS PER CUST | J1: JML STOK DOSIS PER CUST | L1: TGL STOK KELUAR | M1: JAM STOK KELUAR | N1: STOK PROD. KELUAR PER CUST | R1: SISA STOK PROD | V1: CUSTOMER | W1: TERAPIS
A3: 1 | B3: LOREAL HAIR SPA | C3: 46230 | D3: 5 | E3: BUAH | F3: 500 | G3: ML | H3: 50 | I3: GR | J3: =+(D3*F3)/H3 -> 50 | K3: PAX | L3: 46235 | M3: 12.00 | N3: 1 | O3: PAX | P3: =+N3*H3 -> 50 | Q3: GR | R3: =+J3-N3 -> 49 | S3: PAX | T3: =+R3*H3 -> 2450 | U3: GR | V3: ANA | W3: WULAN
A4: =+A3+1 -> 2 | B4: POMPIA HAIR SPA | D4: 3 | E4: BUAH | F4: 1000 | G4: ML | H4: 50 | I4: GR | J4: =+(D4*F4)/H4 -> 60 | K4: PAX | M4: 10.00 | N4: 2 | O4: PAX | P4: =+N4*H4 -> 100 | Q4: GR | R4: =+J4-N4 -> 58 | S4: PAX | T4: =+R4*H4 -> 2900 | U4: GR
A5: =+A4+1 -> 3 | B5: TUMITKU OBAT CALLUS | D5: 12 | E5: BUAH | F5: 30 | G5: ML | H5: 15 | I5: ML | J5: =+(D5*F5)/H5 -> 24 | K5: PAX | M5: 17.00 | N5: 2 | O5: PAX | P5: =+N5*H5 -> 30 | Q5: GR | R5: =+J5-N5 -> 22 | S5: PAX | T5: =+R5*H5 -> 330 | U5: GR
A6: =+A5+1 -> 4 | B6: LOREAL SCALP KETOMBE | D6: 2 | E6: BUAH | F6: 150 | G6: ML | H6: 12 | I6: ML | J6: =+(D6*F6)/H6 -> 25 | K6: PAX | M6: 16.00 | N6: 2 | O6: PAX | P6: =+N6*H6 -> 24 | Q6: GR | R6: =+J6-N6 -> 23 | S6: PAX | T6: =+R6*H6 -> 276 | U6: GR
A7: =+A6+1 -> 5 | B7: SERUM ERHA HAIR GROWTH | D7: 7 | E7: BUAH | F7: 8 | G7: ML | H7: 2.5 | I7: ML | J7: =+(D7*F7)/H7 -> 22.4 | K7: PAX | M7: 12.00 | N7: 3 | O7: PAX | P7: =+N7*H7 -> 7.5 | Q7: ML | R7: =+J7-N7 -> 19.4 | S7: PAX | T7: =+R7*H7 -> 48.5 | U7: ML
